<?xml version='1.0'?>

<robot name="my_robot" xmlns:xacro="http://www.ros.org/wiki/xacro">

<xacro:include filename="$(find my_robot)/urdf/my_robot.gazebo" />

  <link name="robot_footprint"></link>
   <!-- Wheels -->
  <link name="left_wheel">
  <inertial>
      <mass value="5.0"/>
      <origin xyz="0.0 0 0" rpy=" 0 0 0"/>
      <inertia
	  ixx="0.1" ixy="0" ixz="0"
	  iyy="0.1" iyz="0"
	  izz="0.1"
      />
    </inertial>
	<collision name="collision">
  <origin xyz="0 0 0" rpy=" 0 1.5707 1.5707"/>
	  <geometry>
	    <cylinder radius="0.1"  length="0.05" />
	  </geometry>
	</collision>
	<visual>
  <origin xyz="0 0 0" rpy=" 0 1.5707 1.5707"/>
	  <geometry>
	  <cylinder radius="0.1"  length="0.05" />
	  </geometry>
	</visual>
  </link>



  <joint type="continuous" name="left_wheel_hinge">
    <origin xyz="0 0.230 0" rpy="0 0 0"/>
    <child link="left_wheel"/>
    <parent link="chassis"/>
    <axis xyz="0 1 0" rpy="0 0 0"/>
    <limit effort="10000" velocity="1000"/>
    <dynamics damping="1.0" friction="1.0"/>
  </joint>


    <link name="right_wheel">
      <inertial>
      <mass value="5.0"/>
      <origin xyz="0.0 0 0" rpy=" 0 0 0"/>
      <inertia
	  ixx="0.1" ixy="0" ixz="0"
	  iyy="0.1" iyz="0"
	  izz="0.1"
      />
    </inertial>
	<collision name="collision">
	  <origin xyz="0 0 0" rpy=" 0 1.5707 1.5707"/>
	  <geometry>
	    <cylinder radius="0.1"  length="0.05" />
	  </geometry>
	</collision>
	<visual>
	  <origin xyz="0 0 0" rpy=" 0 1.5707 1.5707"/>
	  <geometry>
	  <cylinder radius="0.1"  length="0.05" />
	  </geometry>
	</visual>
    </link>



  <joint type="continuous" name="right_wheel_hinge">
    <origin xyz="0 -0.230 0" rpy="0 0 0"/>
    <child link="right_wheel"/>
    <parent link="chassis"/>
    <axis xyz="0 1 0" rpy="0 0 0"/>
    <limit effort="10000" velocity="1000"/>
    <dynamics damping="1.0" friction="1.0"/>
  </joint>

   <!-- Camera platform -->
   <link name="camera_platform">
       <pose>0 0 0 0 0 0</pose>
    <inertial>
      <mass value="1.0"/>
      <origin xyz="0.0 0 0" rpy=" 0 0 0"/>
      <inertia
        ixx="0.1" ixy="0" ixz="0"
        iyy="0.1" iyz="0"
        izz="0.1"
      />
    </inertial>

    <collision name='collision'>
      <origin xyz="0 0 0" rpy=" 0 0 0"/>
      <geometry>
      <cylinder length="0.05" radius="0.15"/>
      </geometry>
    </collision>
    <visual>
      <origin xyz="0 0 0" rpy=" 0 0 0"/>
      <geometry>

      <cylinder length="0.05" radius="0.15"/>
      </geometry>
    </visual>
   </link>

    <joint type="continuous" name="camera_platform_joint">
    <dynamics friction='0.05'/>
    <origin xyz="0 0 0.225" rpy="0 0 0"/>
      <limit effort="30" velocity="1.0"/>
    <child link="camera_platform"/>
    <parent link="chassis"/>
    <axis xyz="0 0 1" rpy="0 0 0"/>
  </joint>

  <transmission name="camera_platformtransmission">
    <type>transmission_interface/SimpleTransmission</type>
    <joint name="camera_platform_joint">
      <hardwareInterface>hardware_interface/EffortJointInterface</hardwareInterface>
    </joint>
    <actuator name="camera_platform_joint">
      <hardwareInterface>EffortJointInterface</hardwareInterface>
      <mechanicalReduction>1</mechanicalReduction>
    </actuator>
  </transmission>

   <!-- Camera -->

  <link name="camera">
      <inertial>
      <mass value="0.1"/>
      <origin xyz="0.0 0 0" rpy=" 0 0 0"/>
      <inertia  ixx="1e-6" ixy="0" ixz="0" iyy="1e-6" iyz="0" izz="1e-6"/>
      <box_inertia m="0.1" x="0.05" y="0.05" z="0.05"/>
     </inertial>
	<collision name="collision">
	  <origin xyz="0 0 0" rpy=" 0 0 0"/>
	  <geometry>
		<box size="0.05 0.05 0.05"/>
	  </geometry>
	</collision>
	<visual>
	  <origin xyz="0 0 0" rpy=" 0 0 0"/>
	  <geometry>
		<box size="0.05 0.05 0.05"/>
	  </geometry>

	</visual>
  </link>


  <link name="camera_link_optical">
  </link>


  <joint type="fixed" name="camera_joint">
    <origin xyz="0.13 0 0" rpy="0 0 0"/>
    <child link="camera"/>
    <parent link="camera_platform"/>
    <axis xyz="0 0 0" rpy="0 0 0"/>
  </joint>

   <joint name="camera_optical_joint" type="fixed">
    <origin xyz="0 0 0" rpy="-1.5707 0 -1.5707"/>
    <parent link="camera"/>
    <child link="camera_link_optical"/>
  </joint>


   <!-- Lidar platform -->

  <link name="lidar_platform">
    <pose>0 0 0 0 0 0</pose>
    <inertial>
      <mass value="1.0"/>
      <origin xyz="0.0 0 0" rpy=" 0 0 0"/>
      <inertia
	  ixx="0.1" ixy="0" ixz="0"
	  iyy="0.1" iyz="0"
	  izz="0.1"
      />
    </inertial>

    <collision name='collision'>
      <origin xyz="0 0 0" rpy=" 0 0 0"/>
      <geometry>
      <cylinder length="0.05" radius="0.1"/>
      </geometry>
    </collision>

    <visual>
      <origin xyz="0 0 0" rpy=" 0 0 0"/>
      <geometry>

      <cylinder length="0.05" radius="0.1"/>
      </geometry>
    </visual>

  </link>

    <joint type="fixed" name="lidar_platform_join">
    <origin xyz="0 0 0.3" rpy="0 0 0"/>
    <child link="lidar_platform"/>
    <parent link="chassis"/>
    <axis xyz="0 1 0" rpy="0 0 0"/>
  </joint>

 <!-- Lidar -->

    <link name="hokuyo">
      <inertial>
      <mass value="1e-5"/>
      <origin xyz="0.0 0 0" rpy=" 0 0 0"/>
      <inertia  ixx="1e-6" ixy="0" ixz="0" iyy="1e-6" iyz="0" izz="1e-6"/>
      <box_inertia m="0.1" x="0.05" y="0.05" z="0.05"/>
     </inertial>
	<collision name="collision">
	  <origin xyz="0 0 0" rpy=" 0 0 0"/>
	  <geometry>
		<box size="0.01 0.01 0.01"/>
	  </geometry>
	</collision>
	<visual name="visual">
	  <geometry>
	    <mesh filename="package://my_robot/meshes/hokuyo.dae">
	    </mesh>
	    </geometry>
	  </visual>
    </link>

  <joint type="fixed" name="hokuyo_joint">
    <origin xyz="0 0 0.05" rpy="0 0 0"/>
    <child link="hokuyo"/>
    <parent link="lidar_platform"/>
    <axis xyz="0 1 0" rpy="0 0 0"/>
  </joint>

  <joint name="robot_footprint_joint" type="fixed">
    <origin xyz="0 0 0" rpy="0 0 0" />
    <parent link="robot_footprint"/>
    <child link="chassis" />
  </joint>


<!-- chassis -->

  <link name='chassis'>
    <pose>0 0 0.1 0 0 0</pose>

    <inertial>
      <mass value="15.0"/>
      <origin xyz="0.0 0 0" rpy=" 0 0 0"/>
      <inertia
	  ixx="0.1" ixy="0" ixz="0"
	  iyy="0.1" iyz="0"
	  izz="0.1"
      />
    </inertial>

    <collision name='collision'>
      <origin xyz="0 0 0" rpy=" 0 0 0"/>
      <geometry>
 <!--	<box size="0.4 0.2 0.1"/>  -->
      <cylinder length="0.1" radius="0.2"/>
      </geometry>
    </collision>

    <visual>
      <origin xyz="0 0 0.05" rpy=" 0 0 0"/>
      <geometry>

	 <!-- <box size="0.4 0.2 0.1"/> -->
      <cylinder length="0.2" radius="0.2"/>
      </geometry>
    </visual>


    <collision name='back_caster_collision'>
      <origin xyz="-0.15 0 -0.05" rpy=" 0 0 0"/>
      <geometry>
	<sphere radius="0.0499"/>
      </geometry>
    </collision>

    <visual name='back_caster_visual'>
      <origin xyz="-0.15 0 -0.05" rpy=" 0 0 0"/>
      <geometry>
	<sphere radius="0.05"/>
      </geometry>
    </visual>

    <collision name='front_caster_collision'>
      <origin xyz="0.15 0 -0.05" rpy=" 0 0 0"/>
      <geometry>
	<sphere radius="0.0499"/>
      </geometry>
    </collision>

    <visual name='front_caster_visual'>
      <origin xyz="0.15 0 -0.05" rpy=" 0 0 0"/>
      <geometry>
	<sphere radius="0.05"/>
      </geometry>
    </visual>

  </link>

</robot>
